<?xml version="1.0" encoding="UTF-8"?>
<testng-results skipped="0" failed="2" total="4" passed="2">
  <reporter-output>
  </reporter-output>
  <suite name="Default suite" duration-ms="4043" started-at="2017-06-21T04:28:09Z" finished-at="2017-06-21T04:28:13Z">
    <groups>
    </groups>
    <test name="Default test" duration-ms="4043" started-at="2017-06-21T04:28:09Z" finished-at="2017-06-21T04:28:13Z">
      <class name="com.webservice.customer.test.TestCustomerWS_Testng">
        <test-method status="PASS" signature="testWithValidData()[pri:0, instance:com.webservice.customer.test.TestCustomerWS_Testng@1810399e]" name="testWithValidData" duration-ms="1027" started-at="2017-06-20T21:28:09Z" finished-at="2017-06-20T21:28:10Z">
          <reporter-output>
          </reporter-output>
        </test-method> <!-- testWithValidData -->
        <test-method status="PASS" signature="testWithInvalidData()[pri:0, instance:com.webservice.customer.test.TestCustomerWS_Testng@1810399e]" name="testWithInvalidData" duration-ms="471" started-at="2017-06-20T21:28:10Z" finished-at="2017-06-20T21:28:11Z">
          <reporter-output>
          </reporter-output>
        </test-method> <!-- testWithInvalidData -->
        <test-method status="FAIL" signature="testSuccessPost()[pri:0, instance:com.webservice.customer.test.TestCustomerWS_Testng@1810399e]" name="testSuccessPost" duration-ms="1372" started-at="2017-06-20T21:28:11Z" finished-at="2017-06-20T21:28:12Z">
          <exception class="java.lang.AssertionError">
            <message>
              <![CDATA[expected [201] but found [500]]]>
            </message>
            <full-stacktrace>
              <![CDATA[java.lang.AssertionError: expected [201] but found [500]
	at org.testng.Assert.fail(Assert.java:94)
	at org.testng.Assert.failNotEquals(Assert.java:494)
	at org.testng.Assert.assertEquals(Assert.java:123)
	at org.testng.Assert.assertEquals(Assert.java:370)
	at org.testng.Assert.assertEquals(Assert.java:380)
	at com.webservice.core.ServiceValidationUtil.performStandardValidationsForPost(ServiceValidationUtil.java:33)
	at com.webservice.customer.test.TestCustomerWS_Testng.testSuccessPost(TestCustomerWS_Testng.java:68)
	at sun.reflect.NativeMethodAccessorImpl.invoke0(Native Method)
	at sun.reflect.NativeMethodAccessorImpl.invoke(NativeMethodAccessorImpl.java:62)
	at sun.reflect.DelegatingMethodAccessorImpl.invoke(DelegatingMethodAccessorImpl.java:43)
	at java.lang.reflect.Method.invoke(Method.java:498)
	at org.testng.internal.MethodInvocationHelper.invokeMethod(MethodInvocationHelper.java:84)
	at org.testng.internal.Invoker.invokeMethod(Invoker.java:714)
	at org.testng.internal.Invoker.invokeTestMethod(Invoker.java:901)
	at org.testng.internal.Invoker.invokeTestMethods(Invoker.java:1231)
	at org.testng.internal.TestMethodWorker.invokeTestMethods(TestMethodWorker.java:127)
	at org.testng.internal.TestMethodWorker.run(TestMethodWorker.java:111)
	at org.testng.TestRunner.privateRun(TestRunner.java:767)
	at org.testng.TestRunner.run(TestRunner.java:617)
	at org.testng.SuiteRunner.runTest(SuiteRunner.java:348)
	at org.testng.SuiteRunner.runSequentially(SuiteRunner.java:343)
	at org.testng.SuiteRunner.privateRun(SuiteRunner.java:305)
	at org.testng.SuiteRunner.run(SuiteRunner.java:254)
	at org.testng.SuiteRunnerWorker.runSuite(SuiteRunnerWorker.java:52)
	at org.testng.SuiteRunnerWorker.run(SuiteRunnerWorker.java:86)
	at org.testng.TestNG.runSuitesSequentially(TestNG.java:1224)
	at org.testng.TestNG.runSuitesLocally(TestNG.java:1149)
	at org.testng.TestNG.run(TestNG.java:1057)
	at org.testng.remote.AbstractRemoteTestNG.run(AbstractRemoteTestNG.java:132)
	at org.testng.remote.RemoteTestNG.initAndRun(RemoteTestNG.java:230)
	at org.testng.remote.RemoteTestNG.main(RemoteTestNG.java:76)
]]>
            </full-stacktrace>
          </exception> <!-- java.lang.AssertionError -->
          <reporter-output>
          </reporter-output>
        </test-method> <!-- testSuccessPost -->
        <test-method status="FAIL" signature="testSuccessfulDelete()[pri:0, instance:com.webservice.customer.test.TestCustomerWS_Testng@1810399e]" name="testSuccessfulDelete" duration-ms="1153" started-at="2017-06-20T21:28:12Z" finished-at="2017-06-20T21:28:13Z">
          <exception class="java.lang.AssertionError">
            <message>
              <![CDATA[expected [200] but found [404]]]>
            </message>
            <full-stacktrace>
              <![CDATA[java.lang.AssertionError: expected [200] but found [404]
	at org.testng.Assert.fail(Assert.java:94)
	at org.testng.Assert.failNotEquals(Assert.java:494)
	at org.testng.Assert.assertEquals(Assert.java:123)
	at org.testng.Assert.assertEquals(Assert.java:370)
	at org.testng.Assert.assertEquals(Assert.java:380)
	at com.webservice.core.ServiceValidationUtil.performStandardValidationsForDelete(ServiceValidationUtil.java:38)
	at com.webservice.customer.test.TestCustomerWS_Testng.testSuccessfulDelete(TestCustomerWS_Testng.java:83)
	at sun.reflect.NativeMethodAccessorImpl.invoke0(Native Method)
	at sun.reflect.NativeMethodAccessorImpl.invoke(NativeMethodAccessorImpl.java:62)
	at sun.reflect.DelegatingMethodAccessorImpl.invoke(DelegatingMethodAccessorImpl.java:43)
	at java.lang.reflect.Method.invoke(Method.java:498)
	at org.testng.internal.MethodInvocationHelper.invokeMethod(MethodInvocationHelper.java:84)
	at org.testng.internal.Invoker.invokeMethod(Invoker.java:714)
	at org.testng.internal.Invoker.invokeTestMethod(Invoker.java:901)
	at org.testng.internal.Invoker.invokeTestMethods(Invoker.java:1231)
	at org.testng.internal.TestMethodWorker.invokeTestMethods(TestMethodWorker.java:127)
	at org.testng.internal.TestMethodWorker.run(TestMethodWorker.java:111)
	at org.testng.TestRunner.privateRun(TestRunner.java:767)
	at org.testng.TestRunner.run(TestRunner.java:617)
	at org.testng.SuiteRunner.runTest(SuiteRunner.java:348)
	at org.testng.SuiteRunner.runSequentially(SuiteRunner.java:343)
	at org.testng.SuiteRunner.privateRun(SuiteRunner.java:305)
	at org.testng.SuiteRunner.run(SuiteRunner.java:254)
	at org.testng.SuiteRunnerWorker.runSuite(SuiteRunnerWorker.java:52)
	at org.testng.SuiteRunnerWorker.run(SuiteRunnerWorker.java:86)
	at org.testng.TestNG.runSuitesSequentially(TestNG.java:1224)
	at org.testng.TestNG.runSuitesLocally(TestNG.java:1149)
	at org.testng.TestNG.run(TestNG.java:1057)
	at org.testng.remote.AbstractRemoteTestNG.run(AbstractRemoteTestNG.java:132)
	at org.testng.remote.RemoteTestNG.initAndRun(RemoteTestNG.java:230)
	at org.testng.remote.RemoteTestNG.main(RemoteTestNG.java:76)
]]>
            </full-stacktrace>
          </exception> <!-- java.lang.AssertionError -->
          <reporter-output>
          </reporter-output>
        </test-method> <!-- testSuccessfulDelete -->
      </class> <!-- com.webservice.customer.test.TestCustomerWS_Testng -->
    </test> <!-- Default test -->
  </suite> <!-- Default suite -->
</testng-results>
